2025-07-13 21:37:13,035 INFO    MainThread:3727384 [wandb_setup.py:_flush():68] Current SDK version is 0.19.10
2025-07-13 21:37:13,035 INFO    MainThread:3727384 [wandb_setup.py:_flush():68] Configure stats pid to 3727384
2025-07-13 21:37:13,035 INFO    MainThread:3727384 [wandb_setup.py:_flush():68] Loading settings from /home/mingzhi/.config/wandb/settings
2025-07-13 21:37:13,035 INFO    MainThread:3727384 [wandb_setup.py:_flush():68] Loading settings from /nvme2/mingzhi/NucCorr/correct_baseline/ASM/wandb/settings
2025-07-13 21:37:13,035 INFO    MainThread:3727384 [wandb_setup.py:_flush():68] Loading settings from environment variables
2025-07-13 21:37:13,035 INFO    MainThread:3727384 [wandb_init.py:setup_run_log_directory():724] Logging user logs to /nvme2/mingzhi/NucCorr/correct_baseline/ASM/wandb/run-20250713_213713-mgvm8dor/logs/debug.log
2025-07-13 21:37:13,035 INFO    MainThread:3727384 [wandb_init.py:setup_run_log_directory():725] Logging internal logs to /nvme2/mingzhi/NucCorr/correct_baseline/ASM/wandb/run-20250713_213713-mgvm8dor/logs/debug-internal.log
2025-07-13 21:37:13,036 INFO    MainThread:3727384 [wandb_init.py:init():852] calling init triggers
2025-07-13 21:37:13,036 INFO    MainThread:3727384 [wandb_init.py:init():857] wandb.init called with sweep_config: {}
config: {'data_dir': '/nvme2/mingzhi/NucCorr/NucCorrData/normal_nuclei/normal_nuclei', 'train_file': '/nvme2/mingzhi/NucCorr/NucCorrData/normal_nuclei/normal_nuclei/normal_nuclei_train.txt', 'val_file': '/nvme2/mingzhi/NucCorr/NucCorrData/normal_nuclei/normal_nuclei/normal_nuclei_val.txt', 'pca_path': '/nvme2/mingzhi/NucCorr/NucCorrData/normal_nuclei/normal_nuclei/shape_model.npz', 'batch_size': 4, 'epochs': 100, 'lr': 0.001, 'weight_decay': 0.0001, 'wandb_key': 'c414fdb4c81a8cd049cb5889fc118e1bfae04b66', 'project_name': 'asm_pointcloud', 'seed': 42, '_wandb': {}}
2025-07-13 21:37:13,036 INFO    MainThread:3727384 [wandb_init.py:init():893] starting backend
2025-07-13 21:37:13,036 INFO    MainThread:3727384 [wandb_init.py:init():897] sending inform_init request
2025-07-13 21:37:13,039 INFO    MainThread:3727384 [backend.py:_multiprocessing_setup():101] multiprocessing start_methods=fork,spawn,forkserver, using: spawn
2025-07-13 21:37:13,039 INFO    MainThread:3727384 [wandb_init.py:init():907] backend started and connected
2025-07-13 21:37:13,041 INFO    MainThread:3727384 [wandb_init.py:init():1002] updated telemetry
2025-07-13 21:37:13,042 INFO    MainThread:3727384 [wandb_init.py:init():1026] communicating run to backend with 90.0 second timeout
2025-07-13 21:37:44,246 INFO    Thread-2 (wrapped_target):3727384 [retry.py:__call__():175] [no run ID] Retry attempt failed:
Traceback (most recent call last):
  File "/home/mingzhi/.conda/envs/pointllm/lib/python3.10/site-packages/urllib3/connection.py", line 198, in _new_conn
    sock = connection.create_connection(
  File "/home/mingzhi/.conda/envs/pointllm/lib/python3.10/site-packages/urllib3/util/connection.py", line 85, in create_connection
    raise err
  File "/home/mingzhi/.conda/envs/pointllm/lib/python3.10/site-packages/urllib3/util/connection.py", line 73, in create_connection
    sock.connect(sa)
TimeoutError: timed out

The above exception was the direct cause of the following exception:

Traceback (most recent call last):
  File "/home/mingzhi/.conda/envs/pointllm/lib/python3.10/site-packages/urllib3/connectionpool.py", line 787, in urlopen
    response = self._make_request(
  File "/home/mingzhi/.conda/envs/pointllm/lib/python3.10/site-packages/urllib3/connectionpool.py", line 488, in _make_request
    raise new_e
  File "/home/mingzhi/.conda/envs/pointllm/lib/python3.10/site-packages/urllib3/connectionpool.py", line 464, in _make_request
    self._validate_conn(conn)
  File "/home/mingzhi/.conda/envs/pointllm/lib/python3.10/site-packages/urllib3/connectionpool.py", line 1093, in _validate_conn
    conn.connect()
  File "/home/mingzhi/.conda/envs/pointllm/lib/python3.10/site-packages/urllib3/connection.py", line 704, in connect
    self.sock = sock = self._new_conn()
  File "/home/mingzhi/.conda/envs/pointllm/lib/python3.10/site-packages/urllib3/connection.py", line 207, in _new_conn
    raise ConnectTimeoutError(
urllib3.exceptions.ConnectTimeoutError: (<urllib3.connection.HTTPSConnection object at 0x7fa8980ed480>, 'Connection to api.wandb.ai timed out. (connect timeout=20)')

The above exception was the direct cause of the following exception:

Traceback (most recent call last):
  File "/home/mingzhi/.conda/envs/pointllm/lib/python3.10/site-packages/requests/adapters.py", line 667, in send
    resp = conn.urlopen(
  File "/home/mingzhi/.conda/envs/pointllm/lib/python3.10/site-packages/urllib3/connectionpool.py", line 841, in urlopen
    retries = retries.increment(
  File "/home/mingzhi/.conda/envs/pointllm/lib/python3.10/site-packages/urllib3/util/retry.py", line 519, in increment
    raise MaxRetryError(_pool, url, reason) from reason  # type: ignore[arg-type]
urllib3.exceptions.MaxRetryError: HTTPSConnectionPool(host='api.wandb.ai', port=443): Max retries exceeded with url: /graphql (Caused by ConnectTimeoutError(<urllib3.connection.HTTPSConnection object at 0x7fa8980ed480>, 'Connection to api.wandb.ai timed out. (connect timeout=20)'))

During handling of the above exception, another exception occurred:

Traceback (most recent call last):
  File "/home/mingzhi/.conda/envs/pointllm/lib/python3.10/site-packages/wandb/sdk/lib/retry.py", line 134, in __call__
    result = self._call_fn(*args, **kwargs)
  File "/home/mingzhi/.conda/envs/pointllm/lib/python3.10/site-packages/wandb/sdk/internal/internal_api.py", line 402, in execute
    return self.client.execute(*args, **kwargs)  # type: ignore
  File "/home/mingzhi/.conda/envs/pointllm/lib/python3.10/site-packages/wandb/vendor/gql-0.2.0/wandb_gql/client.py", line 52, in execute
    result = self._get_result(document, *args, **kwargs)
  File "/home/mingzhi/.conda/envs/pointllm/lib/python3.10/site-packages/wandb/vendor/gql-0.2.0/wandb_gql/client.py", line 60, in _get_result
    return self.transport.execute(document, *args, **kwargs)
  File "/home/mingzhi/.conda/envs/pointllm/lib/python3.10/site-packages/wandb/sdk/lib/gql_request.py", line 58, in execute
    request = self.session.post(self.url, **post_args)
  File "/home/mingzhi/.conda/envs/pointllm/lib/python3.10/site-packages/requests/sessions.py", line 637, in post
    return self.request("POST", url, data=data, json=json, **kwargs)
  File "/home/mingzhi/.conda/envs/pointllm/lib/python3.10/site-packages/requests/sessions.py", line 589, in request
    resp = self.send(prep, **send_kwargs)
  File "/home/mingzhi/.conda/envs/pointllm/lib/python3.10/site-packages/requests/sessions.py", line 703, in send
    r = adapter.send(request, **kwargs)
  File "/home/mingzhi/.conda/envs/pointllm/lib/python3.10/site-packages/requests/adapters.py", line 688, in send
    raise ConnectTimeout(e, request=request)
requests.exceptions.ConnectTimeout: HTTPSConnectionPool(host='api.wandb.ai', port=443): Max retries exceeded with url: /graphql (Caused by ConnectTimeoutError(<urllib3.connection.HTTPSConnection object at 0x7fa8980ed480>, 'Connection to api.wandb.ai timed out. (connect timeout=20)'))
2025-07-13 21:38:14,871 WARNING MainThread:3727384 [wandb_init.py:init():1654] [no run ID] interrupted
Traceback (most recent call last):
  File "/home/mingzhi/.conda/envs/pointllm/lib/python3.10/site-packages/wandb/sdk/wandb_init.py", line 1650, in init
    return wi.init(run_settings, run_config, run_printer)
  File "/home/mingzhi/.conda/envs/pointllm/lib/python3.10/site-packages/wandb/sdk/wandb_init.py", line 1052, in init
    result = wait_with_progress(
  File "/home/mingzhi/.conda/envs/pointllm/lib/python3.10/site-packages/wandb/sdk/mailbox/wait_with_progress.py", line 24, in wait_with_progress
    return wait_all_with_progress(
  File "/home/mingzhi/.conda/envs/pointllm/lib/python3.10/site-packages/wandb/sdk/mailbox/wait_with_progress.py", line 87, in wait_all_with_progress
    return asyncio_compat.run(progress_loop_with_timeout)
  File "/home/mingzhi/.conda/envs/pointllm/lib/python3.10/site-packages/wandb/sdk/lib/asyncio_compat.py", line 30, in run
    return future.result()
  File "/home/mingzhi/.conda/envs/pointllm/lib/python3.10/concurrent/futures/_base.py", line 453, in result
    self._condition.wait(timeout)
  File "/home/mingzhi/.conda/envs/pointllm/lib/python3.10/threading.py", line 320, in wait
    waiter.acquire()
KeyboardInterrupt
